INFO:apscheduler.scheduler:Scheduler started
WARNING:py.warnings:/usr/local/lib/python2.7/dist-packages/django/db/models/fields/__init__.py:1453: RuntimeWarning: DateTimeField Battle.battle_end received a naive datetime (2016-03-10 14:32:35.588164) while time zone support is active.
  RuntimeWarning)

INFO:root:[<Battle: Featured>]
INFO:requests.packages.urllib3.connectionpool:Starting new HTTPS connection (1): twitter.com
WARNING:py.warnings:/usr/local/lib/python2.7/dist-packages/requests/packages/urllib3/util/ssl_.py:315: SNIMissingWarning: An HTTPS request has been made, but the SNI (Subject Name Indication) extension to TLS is not available on this platform. This may cause the server to present an incorrect TLS certificate, which can cause validation failures. For more information, see https://urllib3.readthedocs.org/en/latest/security.html#snimissingwarning.
  SNIMissingWarning

WARNING:py.warnings:/usr/local/lib/python2.7/dist-packages/requests/packages/urllib3/util/ssl_.py:120: InsecurePlatformWarning: A true SSLContext object is not available. This prevents urllib3 from configuring SSL appropriately and may cause certain SSL connections to fail. For more information, see https://urllib3.readthedocs.org/en/latest/security.html#insecureplatformwarning.
  InsecurePlatformWarning

INFO:requests.packages.urllib3.connectionpool:Starting new HTTPS connection (1): twitter.com
WARNING:py.warnings:/usr/local/lib/python2.7/dist-packages/requests/packages/urllib3/util/ssl_.py:120: InsecurePlatformWarning: A true SSLContext object is not available. This prevents urllib3 from configuring SSL appropriately and may cause certain SSL connections to fail. For more information, see https://urllib3.readthedocs.org/en/latest/security.html#insecureplatformwarning.
  InsecurePlatformWarning

ERROR:django.request:Internal Server Error: /battles/start_crawling/
Traceback (most recent call last):
  File "/usr/local/lib/python2.7/dist-packages/django/core/handlers/base.py", line 149, in get_response
    response = self.process_exception_by_middleware(e, request)
  File "/usr/local/lib/python2.7/dist-packages/django/core/handlers/base.py", line 147, in get_response
    response = wrapped_callback(request, *callback_args, **callback_kwargs)
  File "/home/neelu/twitter_crawl/hashtagbattle/views.py", line 156, in start_crawling
    crawl_twitter(request)
  File "/home/neelu/twitter_crawl/hashtagbattle/views.py", line 190, in crawl_twitter
    #@SCHEDULER.interval_schedule(hours=1)
AttributeError: 'dict' object has no attribute 'battle_name'
INFO:apscheduler.scheduler:Scheduler started
INFO:requests.packages.urllib3.connectionpool:Starting new HTTPS connection (1): twitter.com
WARNING:py.warnings:/usr/local/lib/python2.7/dist-packages/requests/packages/urllib3/util/ssl_.py:315: SNIMissingWarning: An HTTPS request has been made, but the SNI (Subject Name Indication) extension to TLS is not available on this platform. This may cause the server to present an incorrect TLS certificate, which can cause validation failures. For more information, see https://urllib3.readthedocs.org/en/latest/security.html#snimissingwarning.
  SNIMissingWarning

WARNING:py.warnings:/usr/local/lib/python2.7/dist-packages/requests/packages/urllib3/util/ssl_.py:120: InsecurePlatformWarning: A true SSLContext object is not available. This prevents urllib3 from configuring SSL appropriately and may cause certain SSL connections to fail. For more information, see https://urllib3.readthedocs.org/en/latest/security.html#insecureplatformwarning.
  InsecurePlatformWarning

INFO:requests.packages.urllib3.connectionpool:Starting new HTTPS connection (1): twitter.com
WARNING:py.warnings:/usr/local/lib/python2.7/dist-packages/requests/packages/urllib3/util/ssl_.py:120: InsecurePlatformWarning: A true SSLContext object is not available. This prevents urllib3 from configuring SSL appropriately and may cause certain SSL connections to fail. For more information, see https://urllib3.readthedocs.org/en/latest/security.html#insecureplatformwarning.
  InsecurePlatformWarning

ERROR:django.request:Internal Server Error: /battles/start_crawling/
Traceback (most recent call last):
  File "/usr/local/lib/python2.7/dist-packages/django/core/handlers/base.py", line 149, in get_response
    response = self.process_exception_by_middleware(e, request)
  File "/usr/local/lib/python2.7/dist-packages/django/core/handlers/base.py", line 147, in get_response
    response = wrapped_callback(request, *callback_args, **callback_kwargs)
  File "/home/neelu/twitter_crawl/hashtagbattle/views.py", line 156, in start_crawling
    crawl_twitter(request)
  File "/home/neelu/twitter_crawl/hashtagbattle/views.py", line 193, in crawl_twitter
    def crawl_twitter(request):
  File "/home/neelu/twitter_crawl/hashtagbattle/views.py", line 177, in update_crawl_data
    '''
TypeError: can't compare offset-naive and offset-aware datetimes
INFO:apscheduler.scheduler:Scheduler started
INFO:requests.packages.urllib3.connectionpool:Starting new HTTPS connection (1): twitter.com
WARNING:py.warnings:/usr/local/lib/python2.7/dist-packages/requests/packages/urllib3/util/ssl_.py:315: SNIMissingWarning: An HTTPS request has been made, but the SNI (Subject Name Indication) extension to TLS is not available on this platform. This may cause the server to present an incorrect TLS certificate, which can cause validation failures. For more information, see https://urllib3.readthedocs.org/en/latest/security.html#snimissingwarning.
  SNIMissingWarning

WARNING:py.warnings:/usr/local/lib/python2.7/dist-packages/requests/packages/urllib3/util/ssl_.py:120: InsecurePlatformWarning: A true SSLContext object is not available. This prevents urllib3 from configuring SSL appropriately and may cause certain SSL connections to fail. For more information, see https://urllib3.readthedocs.org/en/latest/security.html#insecureplatformwarning.
  InsecurePlatformWarning

INFO:requests.packages.urllib3.connectionpool:Starting new HTTPS connection (1): twitter.com
WARNING:py.warnings:/usr/local/lib/python2.7/dist-packages/requests/packages/urllib3/util/ssl_.py:120: InsecurePlatformWarning: A true SSLContext object is not available. This prevents urllib3 from configuring SSL appropriately and may cause certain SSL connections to fail. For more information, see https://urllib3.readthedocs.org/en/latest/security.html#insecureplatformwarning.
  InsecurePlatformWarning

ERROR:django.request:Internal Server Error: /battles/start_crawling/
Traceback (most recent call last):
  File "/usr/local/lib/python2.7/dist-packages/django/core/handlers/base.py", line 149, in get_response
    response = self.process_exception_by_middleware(e, request)
  File "/usr/local/lib/python2.7/dist-packages/django/core/handlers/base.py", line 147, in get_response
    response = wrapped_callback(request, *callback_args, **callback_kwargs)
  File "/home/neelu/twitter_crawl/hashtagbattle/views.py", line 156, in start_crawling
    crawl_twitter(request)
  File "/home/neelu/twitter_crawl/hashtagbattle/views.py", line 198, in crawl_twitter
AttributeError: 'dict' object has no attribute 'battle_name'
INFO:requests.packages.urllib3.connectionpool:Starting new HTTPS connection (1): twitter.com
WARNING:py.warnings:/usr/local/lib/python2.7/dist-packages/requests/packages/urllib3/util/ssl_.py:120: InsecurePlatformWarning: A true SSLContext object is not available. This prevents urllib3 from configuring SSL appropriately and may cause certain SSL connections to fail. For more information, see https://urllib3.readthedocs.org/en/latest/security.html#insecureplatformwarning.
  InsecurePlatformWarning

INFO:requests.packages.urllib3.connectionpool:Starting new HTTPS connection (1): twitter.com
WARNING:py.warnings:/usr/local/lib/python2.7/dist-packages/requests/packages/urllib3/util/ssl_.py:120: InsecurePlatformWarning: A true SSLContext object is not available. This prevents urllib3 from configuring SSL appropriately and may cause certain SSL connections to fail. For more information, see https://urllib3.readthedocs.org/en/latest/security.html#insecureplatformwarning.
  InsecurePlatformWarning

INFO:apscheduler.scheduler:Scheduler started
INFO:requests.packages.urllib3.connectionpool:Starting new HTTPS connection (1): twitter.com
WARNING:py.warnings:/usr/local/lib/python2.7/dist-packages/requests/packages/urllib3/util/ssl_.py:315: SNIMissingWarning: An HTTPS request has been made, but the SNI (Subject Name Indication) extension to TLS is not available on this platform. This may cause the server to present an incorrect TLS certificate, which can cause validation failures. For more information, see https://urllib3.readthedocs.org/en/latest/security.html#snimissingwarning.
  SNIMissingWarning

WARNING:py.warnings:/usr/local/lib/python2.7/dist-packages/requests/packages/urllib3/util/ssl_.py:120: InsecurePlatformWarning: A true SSLContext object is not available. This prevents urllib3 from configuring SSL appropriately and may cause certain SSL connections to fail. For more information, see https://urllib3.readthedocs.org/en/latest/security.html#insecureplatformwarning.
  InsecurePlatformWarning

INFO:requests.packages.urllib3.connectionpool:Starting new HTTPS connection (1): twitter.com
WARNING:py.warnings:/usr/local/lib/python2.7/dist-packages/requests/packages/urllib3/util/ssl_.py:120: InsecurePlatformWarning: A true SSLContext object is not available. This prevents urllib3 from configuring SSL appropriately and may cause certain SSL connections to fail. For more information, see https://urllib3.readthedocs.org/en/latest/security.html#insecureplatformwarning.
  InsecurePlatformWarning

ERROR:django.request:Internal Server Error: /battles/start_crawling/
Traceback (most recent call last):
  File "/usr/local/lib/python2.7/dist-packages/django/core/handlers/base.py", line 149, in get_response
    response = self.process_exception_by_middleware(e, request)
  File "/usr/local/lib/python2.7/dist-packages/django/core/handlers/base.py", line 147, in get_response
    response = wrapped_callback(request, *callback_args, **callback_kwargs)
  File "/home/neelu/twitter_crawl/hashtagbattle/views.py", line 156, in start_crawling
    crawl_twitter(request)
  File "/home/neelu/twitter_crawl/hashtagbattle/views.py", line 197, in crawl_twitter
    st = update_crawl_data(battle)
  File "/home/neelu/twitter_crawl/hashtagbattle/views.py", line 183, in update_crawl_data
    tag_num_spell_errors=stats['num_spell'])
  File "/usr/local/lib/python2.7/dist-packages/django/db/models/base.py", line 431, in __init__
    setattr(self, field.name, rel_obj)
  File "/usr/local/lib/python2.7/dist-packages/django/db/models/fields/related_descriptors.py", line 207, in __set__
    self.field.remote_field.model._meta.object_name,
ValueError: Cannot assign "7": "BattleCrawlData.battle_id" must be a "Battle" instance.
INFO:apscheduler.scheduler:Scheduler has been shut down
INFO:apscheduler.scheduler:Scheduler started
INFO:requests.packages.urllib3.connectionpool:Starting new HTTPS connection (1): twitter.com
WARNING:py.warnings:/usr/local/lib/python2.7/dist-packages/requests/packages/urllib3/util/ssl_.py:120: InsecurePlatformWarning: A true SSLContext object is not available. This prevents urllib3 from configuring SSL appropriately and may cause certain SSL connections to fail. For more information, see https://urllib3.readthedocs.org/en/latest/security.html#insecureplatformwarning.
  InsecurePlatformWarning

INFO:requests.packages.urllib3.connectionpool:Starting new HTTPS connection (1): twitter.com
WARNING:py.warnings:/usr/local/lib/python2.7/dist-packages/requests/packages/urllib3/util/ssl_.py:120: InsecurePlatformWarning: A true SSLContext object is not available. This prevents urllib3 from configuring SSL appropriately and may cause certain SSL connections to fail. For more information, see https://urllib3.readthedocs.org/en/latest/security.html#insecureplatformwarning.
  InsecurePlatformWarning

ERROR:django.request:Internal Server Error: /battles/start_crawling/
Traceback (most recent call last):
  File "/usr/local/lib/python2.7/dist-packages/django/core/handlers/base.py", line 149, in get_response
    response = self.process_exception_by_middleware(e, request)
  File "/usr/local/lib/python2.7/dist-packages/django/core/handlers/base.py", line 147, in get_response
    response = wrapped_callback(request, *callback_args, **callback_kwargs)
  File "/home/neelu/twitter_crawl/hashtagbattle/views.py", line 156, in start_crawling
    crawl_twitter(request)
  File "/home/neelu/twitter_crawl/hashtagbattle/views.py", line 197, in crawl_twitter
    st = update_crawl_data(battle)
  File "/home/neelu/twitter_crawl/hashtagbattle/views.py", line 183, in update_crawl_data
    tag_num_spell_errors=stats['num_spell'])
  File "/usr/local/lib/python2.7/dist-packages/django/db/models/base.py", line 431, in __init__
    setattr(self, field.name, rel_obj)
  File "/usr/local/lib/python2.7/dist-packages/django/db/models/fields/related_descriptors.py", line 207, in __set__
    self.field.remote_field.model._meta.object_name,
ValueError: Cannot assign "7": "BattleCrawlData.battle_id" must be a "Battle" instance.
INFO:apscheduler.scheduler:Scheduler started
INFO:requests.packages.urllib3.connectionpool:Starting new HTTPS connection (1): twitter.com
WARNING:py.warnings:/usr/local/lib/python2.7/dist-packages/requests/packages/urllib3/util/ssl_.py:315: SNIMissingWarning: An HTTPS request has been made, but the SNI (Subject Name Indication) extension to TLS is not available on this platform. This may cause the server to present an incorrect TLS certificate, which can cause validation failures. For more information, see https://urllib3.readthedocs.org/en/latest/security.html#snimissingwarning.
  SNIMissingWarning

WARNING:py.warnings:/usr/local/lib/python2.7/dist-packages/requests/packages/urllib3/util/ssl_.py:120: InsecurePlatformWarning: A true SSLContext object is not available. This prevents urllib3 from configuring SSL appropriately and may cause certain SSL connections to fail. For more information, see https://urllib3.readthedocs.org/en/latest/security.html#insecureplatformwarning.
  InsecurePlatformWarning

INFO:requests.packages.urllib3.connectionpool:Starting new HTTPS connection (1): twitter.com
WARNING:py.warnings:/usr/local/lib/python2.7/dist-packages/requests/packages/urllib3/util/ssl_.py:120: InsecurePlatformWarning: A true SSLContext object is not available. This prevents urllib3 from configuring SSL appropriately and may cause certain SSL connections to fail. For more information, see https://urllib3.readthedocs.org/en/latest/security.html#insecureplatformwarning.
  InsecurePlatformWarning

ERROR:django.request:Internal Server Error: /battles/start_crawling/
Traceback (most recent call last):
  File "/usr/local/lib/python2.7/dist-packages/django/core/handlers/base.py", line 149, in get_response
    response = self.process_exception_by_middleware(e, request)
  File "/usr/local/lib/python2.7/dist-packages/django/core/handlers/base.py", line 147, in get_response
    response = wrapped_callback(request, *callback_args, **callback_kwargs)
  File "/home/neelu/twitter_crawl/hashtagbattle/views.py", line 156, in start_crawling
    crawl_twitter(request)
  File "/home/neelu/twitter_crawl/hashtagbattle/views.py", line 197, in crawl_twitter
    for battle in battles:
  File "/home/neelu/twitter_crawl/hashtagbattle/views.py", line 183, in update_crawl_data
    tag_num_tweets=stats['num_tweets'],
  File "/usr/local/lib/python2.7/dist-packages/django/db/models/base.py", line 431, in __init__
    setattr(self, field.name, rel_obj)
  File "/usr/local/lib/python2.7/dist-packages/django/db/models/fields/related_descriptors.py", line 207, in __set__
    self.field.remote_field.model._meta.object_name,
ValueError: Cannot assign "7": "BattleCrawlData.battle_id" must be a "Battle" instance.
INFO:apscheduler.scheduler:Scheduler started
INFO:requests.packages.urllib3.connectionpool:Starting new HTTPS connection (1): twitter.com
WARNING:py.warnings:/usr/local/lib/python2.7/dist-packages/requests/packages/urllib3/util/ssl_.py:315: SNIMissingWarning: An HTTPS request has been made, but the SNI (Subject Name Indication) extension to TLS is not available on this platform. This may cause the server to present an incorrect TLS certificate, which can cause validation failures. For more information, see https://urllib3.readthedocs.org/en/latest/security.html#snimissingwarning.
  SNIMissingWarning

WARNING:py.warnings:/usr/local/lib/python2.7/dist-packages/requests/packages/urllib3/util/ssl_.py:120: InsecurePlatformWarning: A true SSLContext object is not available. This prevents urllib3 from configuring SSL appropriately and may cause certain SSL connections to fail. For more information, see https://urllib3.readthedocs.org/en/latest/security.html#insecureplatformwarning.
  InsecurePlatformWarning

INFO:requests.packages.urllib3.connectionpool:Starting new HTTPS connection (1): twitter.com
WARNING:py.warnings:/usr/local/lib/python2.7/dist-packages/requests/packages/urllib3/util/ssl_.py:120: InsecurePlatformWarning: A true SSLContext object is not available. This prevents urllib3 from configuring SSL appropriately and may cause certain SSL connections to fail. For more information, see https://urllib3.readthedocs.org/en/latest/security.html#insecureplatformwarning.
  InsecurePlatformWarning

ERROR:django.request:Internal Server Error: /battles/start_crawling/
Traceback (most recent call last):
  File "/usr/local/lib/python2.7/dist-packages/django/core/handlers/base.py", line 149, in get_response
    response = self.process_exception_by_middleware(e, request)
  File "/usr/local/lib/python2.7/dist-packages/django/core/handlers/base.py", line 147, in get_response
    response = wrapped_callback(request, *callback_args, **callback_kwargs)
  File "/home/neelu/twitter_crawl/hashtagbattle/views.py", line 156, in start_crawling
    crawl_twitter(request)
  File "/home/neelu/twitter_crawl/hashtagbattle/views.py", line 198, in crawl_twitter
    st = update_crawl_data(battle)
  File "/home/neelu/twitter_crawl/hashtagbattle/views.py", line 184, in update_crawl_data
    tag_num_spell_errors=stats['num_spell'])
  File "/usr/local/lib/python2.7/dist-packages/django/db/models/base.py", line 431, in __init__
    setattr(self, field.name, rel_obj)
  File "/usr/local/lib/python2.7/dist-packages/django/db/models/fields/related_descriptors.py", line 207, in __set__
    self.field.remote_field.model._meta.object_name,
ValueError: Cannot assign "7": "BattleCrawlData.battle_id" must be a "Battle" instance.
INFO:apscheduler.scheduler:Scheduler started
INFO:requests.packages.urllib3.connectionpool:Starting new HTTPS connection (1): twitter.com
WARNING:py.warnings:/usr/local/lib/python2.7/dist-packages/requests/packages/urllib3/util/ssl_.py:315: SNIMissingWarning: An HTTPS request has been made, but the SNI (Subject Name Indication) extension to TLS is not available on this platform. This may cause the server to present an incorrect TLS certificate, which can cause validation failures. For more information, see https://urllib3.readthedocs.org/en/latest/security.html#snimissingwarning.
  SNIMissingWarning

WARNING:py.warnings:/usr/local/lib/python2.7/dist-packages/requests/packages/urllib3/util/ssl_.py:120: InsecurePlatformWarning: A true SSLContext object is not available. This prevents urllib3 from configuring SSL appropriately and may cause certain SSL connections to fail. For more information, see https://urllib3.readthedocs.org/en/latest/security.html#insecureplatformwarning.
  InsecurePlatformWarning

INFO:requests.packages.urllib3.connectionpool:Starting new HTTPS connection (1): twitter.com
WARNING:py.warnings:/usr/local/lib/python2.7/dist-packages/requests/packages/urllib3/util/ssl_.py:120: InsecurePlatformWarning: A true SSLContext object is not available. This prevents urllib3 from configuring SSL appropriately and may cause certain SSL connections to fail. For more information, see https://urllib3.readthedocs.org/en/latest/security.html#insecureplatformwarning.
  InsecurePlatformWarning

ERROR:django.request:Internal Server Error: /battles/start_crawling/
Traceback (most recent call last):
  File "/usr/local/lib/python2.7/dist-packages/django/core/handlers/base.py", line 149, in get_response
    response = self.process_exception_by_middleware(e, request)
  File "/usr/local/lib/python2.7/dist-packages/django/core/handlers/base.py", line 147, in get_response
    response = wrapped_callback(request, *callback_args, **callback_kwargs)
  File "/home/neelu/twitter_crawl/hashtagbattle/views.py", line 156, in start_crawling
    crawl_twitter(request)
  File "/home/neelu/twitter_crawl/hashtagbattle/views.py", line 198, in crawl_twitter
    st = update_crawl_data(battle)
  File "/home/neelu/twitter_crawl/hashtagbattle/views.py", line 184, in update_crawl_data
    tag_num_spell_errors=stats['num_spell'])
  File "/usr/local/lib/python2.7/dist-packages/django/db/models/base.py", line 431, in __init__
    setattr(self, field.name, rel_obj)
  File "/usr/local/lib/python2.7/dist-packages/django/db/models/fields/related_descriptors.py", line 207, in __set__
    self.field.remote_field.model._meta.object_name,
ValueError: Cannot assign "7": "BattleCrawlData.battle_id" must be a "Battle" instance.
INFO:apscheduler.scheduler:Scheduler started
INFO:requests.packages.urllib3.connectionpool:Starting new HTTPS connection (1): twitter.com
WARNING:py.warnings:/usr/local/lib/python2.7/dist-packages/requests/packages/urllib3/util/ssl_.py:315: SNIMissingWarning: An HTTPS request has been made, but the SNI (Subject Name Indication) extension to TLS is not available on this platform. This may cause the server to present an incorrect TLS certificate, which can cause validation failures. For more information, see https://urllib3.readthedocs.org/en/latest/security.html#snimissingwarning.
  SNIMissingWarning

WARNING:py.warnings:/usr/local/lib/python2.7/dist-packages/requests/packages/urllib3/util/ssl_.py:120: InsecurePlatformWarning: A true SSLContext object is not available. This prevents urllib3 from configuring SSL appropriately and may cause certain SSL connections to fail. For more information, see https://urllib3.readthedocs.org/en/latest/security.html#insecureplatformwarning.
  InsecurePlatformWarning

INFO:requests.packages.urllib3.connectionpool:Starting new HTTPS connection (1): twitter.com
WARNING:py.warnings:/usr/local/lib/python2.7/dist-packages/requests/packages/urllib3/util/ssl_.py:120: InsecurePlatformWarning: A true SSLContext object is not available. This prevents urllib3 from configuring SSL appropriately and may cause certain SSL connections to fail. For more information, see https://urllib3.readthedocs.org/en/latest/security.html#insecureplatformwarning.
  InsecurePlatformWarning

ERROR:django.request:Internal Server Error: /battles/start_crawling/
Traceback (most recent call last):
  File "/usr/local/lib/python2.7/dist-packages/django/core/handlers/base.py", line 149, in get_response
    response = self.process_exception_by_middleware(e, request)
  File "/usr/local/lib/python2.7/dist-packages/django/core/handlers/base.py", line 147, in get_response
    response = wrapped_callback(request, *callback_args, **callback_kwargs)
  File "/home/neelu/twitter_crawl/hashtagbattle/views.py", line 156, in start_crawling
    crawl_twitter(request)
  File "/home/neelu/twitter_crawl/hashtagbattle/views.py", line 201, in crawl_twitter
    st = update_crawl_data(battle)
  File "/home/neelu/twitter_crawl/hashtagbattle/views.py", line 187, in update_crawl_data
    tag_num_spell_errors=stats['num_spell'])
  File "/usr/local/lib/python2.7/dist-packages/django/db/models/base.py", line 431, in __init__
    setattr(self, field.name, rel_obj)
  File "/usr/local/lib/python2.7/dist-packages/django/db/models/fields/related_descriptors.py", line 207, in __set__
    self.field.remote_field.model._meta.object_name,
ValueError: Cannot assign "7": "BattleCrawlData.battle_id" must be a "Battle" instance.
INFO:apscheduler.scheduler:Scheduler started
INFO:requests.packages.urllib3.connectionpool:Starting new HTTPS connection (1): twitter.com
WARNING:py.warnings:/usr/local/lib/python2.7/dist-packages/requests/packages/urllib3/util/ssl_.py:315: SNIMissingWarning: An HTTPS request has been made, but the SNI (Subject Name Indication) extension to TLS is not available on this platform. This may cause the server to present an incorrect TLS certificate, which can cause validation failures. For more information, see https://urllib3.readthedocs.org/en/latest/security.html#snimissingwarning.
  SNIMissingWarning

WARNING:py.warnings:/usr/local/lib/python2.7/dist-packages/requests/packages/urllib3/util/ssl_.py:120: InsecurePlatformWarning: A true SSLContext object is not available. This prevents urllib3 from configuring SSL appropriately and may cause certain SSL connections to fail. For more information, see https://urllib3.readthedocs.org/en/latest/security.html#insecureplatformwarning.
  InsecurePlatformWarning

INFO:requests.packages.urllib3.connectionpool:Starting new HTTPS connection (1): twitter.com
WARNING:py.warnings:/usr/local/lib/python2.7/dist-packages/requests/packages/urllib3/util/ssl_.py:120: InsecurePlatformWarning: A true SSLContext object is not available. This prevents urllib3 from configuring SSL appropriately and may cause certain SSL connections to fail. For more information, see https://urllib3.readthedocs.org/en/latest/security.html#insecureplatformwarning.
  InsecurePlatformWarning

ERROR:django.request:Internal Server Error: /battles/start_crawling/
Traceback (most recent call last):
  File "/usr/local/lib/python2.7/dist-packages/django/core/handlers/base.py", line 149, in get_response
    response = self.process_exception_by_middleware(e, request)
  File "/usr/local/lib/python2.7/dist-packages/django/core/handlers/base.py", line 147, in get_response
    response = wrapped_callback(request, *callback_args, **callback_kwargs)
  File "/home/neelu/twitter_crawl/hashtagbattle/views.py", line 156, in start_crawling
    crawl_twitter(request)
  File "/home/neelu/twitter_crawl/hashtagbattle/views.py", line 201, in crawl_twitter
    st = update_crawl_data(battle)
  File "/home/neelu/twitter_crawl/hashtagbattle/views.py", line 187, in update_crawl_data
    tag_num_spell_errors=stats['num_spell'])
  File "/usr/local/lib/python2.7/dist-packages/django/db/models/manager.py", line 122, in manager_method
    return getattr(self.get_queryset(), name)(*args, **kwargs)
  File "/usr/local/lib/python2.7/dist-packages/django/db/models/query.py", line 399, in create
    obj = self.model(**kwargs)
  File "/usr/local/lib/python2.7/dist-packages/django/db/models/base.py", line 431, in __init__
    setattr(self, field.name, rel_obj)
  File "/usr/local/lib/python2.7/dist-packages/django/db/models/fields/related_descriptors.py", line 207, in __set__
    self.field.remote_field.model._meta.object_name,
ValueError: Cannot assign "7": "BattleCrawlData.battle_id" must be a "Battle" instance.
INFO:apscheduler.scheduler:Scheduler started
INFO:requests.packages.urllib3.connectionpool:Starting new HTTPS connection (1): twitter.com
WARNING:py.warnings:/usr/local/lib/python2.7/dist-packages/requests/packages/urllib3/util/ssl_.py:315: SNIMissingWarning: An HTTPS request has been made, but the SNI (Subject Name Indication) extension to TLS is not available on this platform. This may cause the server to present an incorrect TLS certificate, which can cause validation failures. For more information, see https://urllib3.readthedocs.org/en/latest/security.html#snimissingwarning.
  SNIMissingWarning

WARNING:py.warnings:/usr/local/lib/python2.7/dist-packages/requests/packages/urllib3/util/ssl_.py:120: InsecurePlatformWarning: A true SSLContext object is not available. This prevents urllib3 from configuring SSL appropriately and may cause certain SSL connections to fail. For more information, see https://urllib3.readthedocs.org/en/latest/security.html#insecureplatformwarning.
  InsecurePlatformWarning

INFO:requests.packages.urllib3.connectionpool:Starting new HTTPS connection (1): twitter.com
WARNING:py.warnings:/usr/local/lib/python2.7/dist-packages/requests/packages/urllib3/util/ssl_.py:120: InsecurePlatformWarning: A true SSLContext object is not available. This prevents urllib3 from configuring SSL appropriately and may cause certain SSL connections to fail. For more information, see https://urllib3.readthedocs.org/en/latest/security.html#insecureplatformwarning.
  InsecurePlatformWarning

ERROR:django.request:Internal Server Error: /battles/start_crawling/
Traceback (most recent call last):
  File "/usr/local/lib/python2.7/dist-packages/django/core/handlers/base.py", line 149, in get_response
    response = self.process_exception_by_middleware(e, request)
  File "/usr/local/lib/python2.7/dist-packages/django/core/handlers/base.py", line 147, in get_response
    response = wrapped_callback(request, *callback_args, **callback_kwargs)
  File "/home/neelu/twitter_crawl/hashtagbattle/views.py", line 156, in start_crawling
    crawl_twitter(request)
  File "/home/neelu/twitter_crawl/hashtagbattle/views.py", line 201, in crawl_twitter
    st = update_crawl_data(battle)
  File "/home/neelu/twitter_crawl/hashtagbattle/views.py", line 191, in update_crawl_data
    if battle.battle_end <= datetime.now():
TypeError: can't compare offset-naive and offset-aware datetimes
INFO:apscheduler.scheduler:Scheduler started
INFO:requests.packages.urllib3.connectionpool:Starting new HTTPS connection (1): twitter.com
WARNING:py.warnings:/usr/local/lib/python2.7/dist-packages/requests/packages/urllib3/util/ssl_.py:315: SNIMissingWarning: An HTTPS request has been made, but the SNI (Subject Name Indication) extension to TLS is not available on this platform. This may cause the server to present an incorrect TLS certificate, which can cause validation failures. For more information, see https://urllib3.readthedocs.org/en/latest/security.html#snimissingwarning.
  SNIMissingWarning

WARNING:py.warnings:/usr/local/lib/python2.7/dist-packages/requests/packages/urllib3/util/ssl_.py:120: InsecurePlatformWarning: A true SSLContext object is not available. This prevents urllib3 from configuring SSL appropriately and may cause certain SSL connections to fail. For more information, see https://urllib3.readthedocs.org/en/latest/security.html#insecureplatformwarning.
  InsecurePlatformWarning

INFO:requests.packages.urllib3.connectionpool:Starting new HTTPS connection (1): twitter.com
WARNING:py.warnings:/usr/local/lib/python2.7/dist-packages/requests/packages/urllib3/util/ssl_.py:120: InsecurePlatformWarning: A true SSLContext object is not available. This prevents urllib3 from configuring SSL appropriately and may cause certain SSL connections to fail. For more information, see https://urllib3.readthedocs.org/en/latest/security.html#insecureplatformwarning.
  InsecurePlatformWarning

ERROR:django.request:Internal Server Error: /battles/start_crawling/
Traceback (most recent call last):
  File "/usr/local/lib/python2.7/dist-packages/django/core/handlers/base.py", line 149, in get_response
    response = self.process_exception_by_middleware(e, request)
  File "/usr/local/lib/python2.7/dist-packages/django/core/handlers/base.py", line 147, in get_response
    response = wrapped_callback(request, *callback_args, **callback_kwargs)
  File "/home/neelu/twitter_crawl/hashtagbattle/views.py", line 156, in start_crawling
    crawl_twitter(request)
  File "/home/neelu/twitter_crawl/hashtagbattle/views.py", line 203, in crawl_twitter
    st = update_crawl_data(battle)
  File "/home/neelu/twitter_crawl/hashtagbattle/views.py", line 193, in update_crawl_data
    if battle.battle_end <= datetime.now():
TypeError: can't compare offset-naive and offset-aware datetimes
INFO:apscheduler.scheduler:Scheduler started
INFO:requests.packages.urllib3.connectionpool:Starting new HTTPS connection (1): twitter.com
WARNING:py.warnings:/usr/local/lib/python2.7/dist-packages/requests/packages/urllib3/util/ssl_.py:315: SNIMissingWarning: An HTTPS request has been made, but the SNI (Subject Name Indication) extension to TLS is not available on this platform. This may cause the server to present an incorrect TLS certificate, which can cause validation failures. For more information, see https://urllib3.readthedocs.org/en/latest/security.html#snimissingwarning.
  SNIMissingWarning

WARNING:py.warnings:/usr/local/lib/python2.7/dist-packages/requests/packages/urllib3/util/ssl_.py:120: InsecurePlatformWarning: A true SSLContext object is not available. This prevents urllib3 from configuring SSL appropriately and may cause certain SSL connections to fail. For more information, see https://urllib3.readthedocs.org/en/latest/security.html#insecureplatformwarning.
  InsecurePlatformWarning

INFO:requests.packages.urllib3.connectionpool:Starting new HTTPS connection (1): twitter.com
WARNING:py.warnings:/usr/local/lib/python2.7/dist-packages/requests/packages/urllib3/util/ssl_.py:120: InsecurePlatformWarning: A true SSLContext object is not available. This prevents urllib3 from configuring SSL appropriately and may cause certain SSL connections to fail. For more information, see https://urllib3.readthedocs.org/en/latest/security.html#insecureplatformwarning.
  InsecurePlatformWarning

ERROR:django.request:Internal Server Error: /battles/start_crawling/
Traceback (most recent call last):
  File "/usr/local/lib/python2.7/dist-packages/django/core/handlers/base.py", line 149, in get_response
    response = self.process_exception_by_middleware(e, request)
  File "/usr/local/lib/python2.7/dist-packages/django/core/handlers/base.py", line 147, in get_response
    response = wrapped_callback(request, *callback_args, **callback_kwargs)
  File "/home/neelu/twitter_crawl/hashtagbattle/views.py", line 156, in start_crawling
    crawl_twitter(request)
  File "/home/neelu/twitter_crawl/hashtagbattle/views.py", line 205, in crawl_twitter
    st = update_crawl_data(battle)
  File "/home/neelu/twitter_crawl/hashtagbattle/views.py", line 195, in update_crawl_data
    if battle.battle_end <= datetime.now():
TypeError: can't compare offset-naive and offset-aware datetimes
INFO:apscheduler.scheduler:Scheduler started
INFO:requests.packages.urllib3.connectionpool:Starting new HTTPS connection (1): twitter.com
WARNING:py.warnings:/usr/local/lib/python2.7/dist-packages/requests/packages/urllib3/util/ssl_.py:315: SNIMissingWarning: An HTTPS request has been made, but the SNI (Subject Name Indication) extension to TLS is not available on this platform. This may cause the server to present an incorrect TLS certificate, which can cause validation failures. For more information, see https://urllib3.readthedocs.org/en/latest/security.html#snimissingwarning.
  SNIMissingWarning

WARNING:py.warnings:/usr/local/lib/python2.7/dist-packages/requests/packages/urllib3/util/ssl_.py:120: InsecurePlatformWarning: A true SSLContext object is not available. This prevents urllib3 from configuring SSL appropriately and may cause certain SSL connections to fail. For more information, see https://urllib3.readthedocs.org/en/latest/security.html#insecureplatformwarning.
  InsecurePlatformWarning

INFO:requests.packages.urllib3.connectionpool:Starting new HTTPS connection (1): twitter.com
WARNING:py.warnings:/usr/local/lib/python2.7/dist-packages/requests/packages/urllib3/util/ssl_.py:120: InsecurePlatformWarning: A true SSLContext object is not available. This prevents urllib3 from configuring SSL appropriately and may cause certain SSL connections to fail. For more information, see https://urllib3.readthedocs.org/en/latest/security.html#insecureplatformwarning.
  InsecurePlatformWarning

ERROR:django.request:Internal Server Error: /battles/start_crawling/
Traceback (most recent call last):
  File "/usr/local/lib/python2.7/dist-packages/django/core/handlers/base.py", line 149, in get_response
    response = self.process_exception_by_middleware(e, request)
  File "/usr/local/lib/python2.7/dist-packages/django/core/handlers/base.py", line 147, in get_response
    response = wrapped_callback(request, *callback_args, **callback_kwargs)
  File "/home/neelu/twitter_crawl/hashtagbattle/views.py", line 156, in start_crawling
    crawl_twitter(request)
  File "/home/neelu/twitter_crawl/hashtagbattle/views.py", line 208, in crawl_twitter
    st = update_crawl_data(battle)
  File "/home/neelu/twitter_crawl/hashtagbattle/views.py", line 192, in update_crawl_data
    t = timezone.make_aware(battle.battle_end, timezone.get_current_timezone())
  File "/usr/local/lib/python2.7/dist-packages/django/utils/timezone.py", line 364, in make_aware
    return timezone.localize(value, is_dst=is_dst)
  File "/usr/lib/python2.7/dist-packages/pytz/__init__.py", line 221, in localize
    raise ValueError('Not naive datetime (tzinfo is already set)')
ValueError: Not naive datetime (tzinfo is already set)
INFO:apscheduler.scheduler:Scheduler started
INFO:requests.packages.urllib3.connectionpool:Starting new HTTPS connection (1): twitter.com
WARNING:py.warnings:/usr/local/lib/python2.7/dist-packages/requests/packages/urllib3/util/ssl_.py:315: SNIMissingWarning: An HTTPS request has been made, but the SNI (Subject Name Indication) extension to TLS is not available on this platform. This may cause the server to present an incorrect TLS certificate, which can cause validation failures. For more information, see https://urllib3.readthedocs.org/en/latest/security.html#snimissingwarning.
  SNIMissingWarning

WARNING:py.warnings:/usr/local/lib/python2.7/dist-packages/requests/packages/urllib3/util/ssl_.py:120: InsecurePlatformWarning: A true SSLContext object is not available. This prevents urllib3 from configuring SSL appropriately and may cause certain SSL connections to fail. For more information, see https://urllib3.readthedocs.org/en/latest/security.html#insecureplatformwarning.
  InsecurePlatformWarning

INFO:requests.packages.urllib3.connectionpool:Starting new HTTPS connection (1): twitter.com
WARNING:py.warnings:/usr/local/lib/python2.7/dist-packages/requests/packages/urllib3/util/ssl_.py:120: InsecurePlatformWarning: A true SSLContext object is not available. This prevents urllib3 from configuring SSL appropriately and may cause certain SSL connections to fail. For more information, see https://urllib3.readthedocs.org/en/latest/security.html#insecureplatformwarning.
  InsecurePlatformWarning

ERROR:django.request:Internal Server Error: /battles/start_crawling/
Traceback (most recent call last):
  File "/usr/local/lib/python2.7/dist-packages/django/core/handlers/base.py", line 149, in get_response
    response = self.process_exception_by_middleware(e, request)
  File "/usr/local/lib/python2.7/dist-packages/django/core/handlers/base.py", line 147, in get_response
    response = wrapped_callback(request, *callback_args, **callback_kwargs)
  File "/home/neelu/twitter_crawl/hashtagbattle/views.py", line 156, in start_crawling
    crawl_twitter(request)
  File "/home/neelu/twitter_crawl/hashtagbattle/views.py", line 209, in crawl_twitter
    st = update_crawl_data(battle)
  File "/home/neelu/twitter_crawl/hashtagbattle/views.py", line 195, in update_crawl_data
    print t
NameError: global name 't' is not defined
INFO:apscheduler.scheduler:Scheduler started
INFO:requests.packages.urllib3.connectionpool:Starting new HTTPS connection (1): twitter.com
WARNING:py.warnings:/usr/local/lib/python2.7/dist-packages/requests/packages/urllib3/util/ssl_.py:315: SNIMissingWarning: An HTTPS request has been made, but the SNI (Subject Name Indication) extension to TLS is not available on this platform. This may cause the server to present an incorrect TLS certificate, which can cause validation failures. For more information, see https://urllib3.readthedocs.org/en/latest/security.html#snimissingwarning.
  SNIMissingWarning

WARNING:py.warnings:/usr/local/lib/python2.7/dist-packages/requests/packages/urllib3/util/ssl_.py:120: InsecurePlatformWarning: A true SSLContext object is not available. This prevents urllib3 from configuring SSL appropriately and may cause certain SSL connections to fail. For more information, see https://urllib3.readthedocs.org/en/latest/security.html#insecureplatformwarning.
  InsecurePlatformWarning

INFO:requests.packages.urllib3.connectionpool:Starting new HTTPS connection (1): twitter.com
WARNING:py.warnings:/usr/local/lib/python2.7/dist-packages/requests/packages/urllib3/util/ssl_.py:120: InsecurePlatformWarning: A true SSLContext object is not available. This prevents urllib3 from configuring SSL appropriately and may cause certain SSL connections to fail. For more information, see https://urllib3.readthedocs.org/en/latest/security.html#insecureplatformwarning.
  InsecurePlatformWarning

INFO:apscheduler.scheduler:Scheduler started
INFO:requests.packages.urllib3.connectionpool:Starting new HTTPS connection (1): twitter.com
WARNING:py.warnings:/usr/local/lib/python2.7/dist-packages/requests/packages/urllib3/util/ssl_.py:315: SNIMissingWarning: An HTTPS request has been made, but the SNI (Subject Name Indication) extension to TLS is not available on this platform. This may cause the server to present an incorrect TLS certificate, which can cause validation failures. For more information, see https://urllib3.readthedocs.org/en/latest/security.html#snimissingwarning.
  SNIMissingWarning

WARNING:py.warnings:/usr/local/lib/python2.7/dist-packages/requests/packages/urllib3/util/ssl_.py:120: InsecurePlatformWarning: A true SSLContext object is not available. This prevents urllib3 from configuring SSL appropriately and may cause certain SSL connections to fail. For more information, see https://urllib3.readthedocs.org/en/latest/security.html#insecureplatformwarning.
  InsecurePlatformWarning

INFO:requests.packages.urllib3.connectionpool:Starting new HTTPS connection (1): twitter.com
WARNING:py.warnings:/usr/local/lib/python2.7/dist-packages/requests/packages/urllib3/util/ssl_.py:120: InsecurePlatformWarning: A true SSLContext object is not available. This prevents urllib3 from configuring SSL appropriately and may cause certain SSL connections to fail. For more information, see https://urllib3.readthedocs.org/en/latest/security.html#insecureplatformwarning.
  InsecurePlatformWarning

INFO:apscheduler.scheduler:Scheduler has been shut down
INFO:apscheduler.scheduler:Scheduler started
INFO:requests.packages.urllib3.connectionpool:Starting new HTTPS connection (1): twitter.com
WARNING:py.warnings:/usr/local/lib/python2.7/dist-packages/requests/packages/urllib3/util/ssl_.py:120: InsecurePlatformWarning: A true SSLContext object is not available. This prevents urllib3 from configuring SSL appropriately and may cause certain SSL connections to fail. For more information, see https://urllib3.readthedocs.org/en/latest/security.html#insecureplatformwarning.
  InsecurePlatformWarning

INFO:requests.packages.urllib3.connectionpool:Starting new HTTPS connection (1): twitter.com
WARNING:py.warnings:/usr/local/lib/python2.7/dist-packages/requests/packages/urllib3/util/ssl_.py:120: InsecurePlatformWarning: A true SSLContext object is not available. This prevents urllib3 from configuring SSL appropriately and may cause certain SSL connections to fail. For more information, see https://urllib3.readthedocs.org/en/latest/security.html#insecureplatformwarning.
  InsecurePlatformWarning

INFO:apscheduler.scheduler:Scheduler started
INFO:requests.packages.urllib3.connectionpool:Starting new HTTPS connection (1): twitter.com
WARNING:py.warnings:/usr/local/lib/python2.7/dist-packages/requests/packages/urllib3/util/ssl_.py:315: SNIMissingWarning: An HTTPS request has been made, but the SNI (Subject Name Indication) extension to TLS is not available on this platform. This may cause the server to present an incorrect TLS certificate, which can cause validation failures. For more information, see https://urllib3.readthedocs.org/en/latest/security.html#snimissingwarning.
  SNIMissingWarning

WARNING:py.warnings:/usr/local/lib/python2.7/dist-packages/requests/packages/urllib3/util/ssl_.py:120: InsecurePlatformWarning: A true SSLContext object is not available. This prevents urllib3 from configuring SSL appropriately and may cause certain SSL connections to fail. For more information, see https://urllib3.readthedocs.org/en/latest/security.html#insecureplatformwarning.
  InsecurePlatformWarning

INFO:requests.packages.urllib3.connectionpool:Starting new HTTPS connection (1): twitter.com
WARNING:py.warnings:/usr/local/lib/python2.7/dist-packages/requests/packages/urllib3/util/ssl_.py:120: InsecurePlatformWarning: A true SSLContext object is not available. This prevents urllib3 from configuring SSL appropriately and may cause certain SSL connections to fail. For more information, see https://urllib3.readthedocs.org/en/latest/security.html#insecureplatformwarning.
  InsecurePlatformWarning

INFO:apscheduler.scheduler:Scheduler started
INFO:requests.packages.urllib3.connectionpool:Starting new HTTPS connection (1): twitter.com
WARNING:py.warnings:/usr/local/lib/python2.7/dist-packages/requests/packages/urllib3/util/ssl_.py:315: SNIMissingWarning: An HTTPS request has been made, but the SNI (Subject Name Indication) extension to TLS is not available on this platform. This may cause the server to present an incorrect TLS certificate, which can cause validation failures. For more information, see https://urllib3.readthedocs.org/en/latest/security.html#snimissingwarning.
  SNIMissingWarning

WARNING:py.warnings:/usr/local/lib/python2.7/dist-packages/requests/packages/urllib3/util/ssl_.py:120: InsecurePlatformWarning: A true SSLContext object is not available. This prevents urllib3 from configuring SSL appropriately and may cause certain SSL connections to fail. For more information, see https://urllib3.readthedocs.org/en/latest/security.html#insecureplatformwarning.
  InsecurePlatformWarning

INFO:requests.packages.urllib3.connectionpool:Starting new HTTPS connection (1): twitter.com
WARNING:py.warnings:/usr/local/lib/python2.7/dist-packages/requests/packages/urllib3/util/ssl_.py:120: InsecurePlatformWarning: A true SSLContext object is not available. This prevents urllib3 from configuring SSL appropriately and may cause certain SSL connections to fail. For more information, see https://urllib3.readthedocs.org/en/latest/security.html#insecureplatformwarning.
  InsecurePlatformWarning

INFO:apscheduler.scheduler:Scheduler started
INFO:requests.packages.urllib3.connectionpool:Starting new HTTPS connection (1): twitter.com
WARNING:py.warnings:/usr/local/lib/python2.7/dist-packages/requests/packages/urllib3/util/ssl_.py:315: SNIMissingWarning: An HTTPS request has been made, but the SNI (Subject Name Indication) extension to TLS is not available on this platform. This may cause the server to present an incorrect TLS certificate, which can cause validation failures. For more information, see https://urllib3.readthedocs.org/en/latest/security.html#snimissingwarning.
  SNIMissingWarning

WARNING:py.warnings:/usr/local/lib/python2.7/dist-packages/requests/packages/urllib3/util/ssl_.py:120: InsecurePlatformWarning: A true SSLContext object is not available. This prevents urllib3 from configuring SSL appropriately and may cause certain SSL connections to fail. For more information, see https://urllib3.readthedocs.org/en/latest/security.html#insecureplatformwarning.
  InsecurePlatformWarning

INFO:requests.packages.urllib3.connectionpool:Starting new HTTPS connection (1): twitter.com
WARNING:py.warnings:/usr/local/lib/python2.7/dist-packages/requests/packages/urllib3/util/ssl_.py:120: InsecurePlatformWarning: A true SSLContext object is not available. This prevents urllib3 from configuring SSL appropriately and may cause certain SSL connections to fail. For more information, see https://urllib3.readthedocs.org/en/latest/security.html#insecureplatformwarning.
  InsecurePlatformWarning

INFO:apscheduler.scheduler:Scheduler started
INFO:requests.packages.urllib3.connectionpool:Starting new HTTPS connection (1): twitter.com
WARNING:py.warnings:/usr/local/lib/python2.7/dist-packages/requests/packages/urllib3/util/ssl_.py:315: SNIMissingWarning: An HTTPS request has been made, but the SNI (Subject Name Indication) extension to TLS is not available on this platform. This may cause the server to present an incorrect TLS certificate, which can cause validation failures. For more information, see https://urllib3.readthedocs.org/en/latest/security.html#snimissingwarning.
  SNIMissingWarning

WARNING:py.warnings:/usr/local/lib/python2.7/dist-packages/requests/packages/urllib3/util/ssl_.py:120: InsecurePlatformWarning: A true SSLContext object is not available. This prevents urllib3 from configuring SSL appropriately and may cause certain SSL connections to fail. For more information, see https://urllib3.readthedocs.org/en/latest/security.html#insecureplatformwarning.
  InsecurePlatformWarning

INFO:requests.packages.urllib3.connectionpool:Starting new HTTPS connection (1): twitter.com
WARNING:py.warnings:/usr/local/lib/python2.7/dist-packages/requests/packages/urllib3/util/ssl_.py:120: InsecurePlatformWarning: A true SSLContext object is not available. This prevents urllib3 from configuring SSL appropriately and may cause certain SSL connections to fail. For more information, see https://urllib3.readthedocs.org/en/latest/security.html#insecureplatformwarning.
  InsecurePlatformWarning

ERROR:django.request:Internal Server Error: /battles/start_crawling/
Traceback (most recent call last):
  File "/usr/local/lib/python2.7/dist-packages/django/core/handlers/base.py", line 149, in get_response
    response = self.process_exception_by_middleware(e, request)
  File "/usr/local/lib/python2.7/dist-packages/django/core/handlers/base.py", line 147, in get_response
    response = wrapped_callback(request, *callback_args, **callback_kwargs)
  File "/home/neelu/twitter_crawl/hashtagbattle/views.py", line 156, in start_crawling
    crawl_twitter(request)
  File "/home/neelu/twitter_crawl/hashtagbattle/views.py", line 203, in crawl_twitter
    for battle in battles:
  File "/home/neelu/twitter_crawl/hashtagbattle/views.py", line 182, in update_crawl_data
    b = BattleCrawlData,objects.update_or_create(battle_id=instance,
NameError: global name 'objects' is not defined
INFO:apscheduler.scheduler:Scheduler started
INFO:requests.packages.urllib3.connectionpool:Starting new HTTPS connection (1): twitter.com
WARNING:py.warnings:/usr/local/lib/python2.7/dist-packages/requests/packages/urllib3/util/ssl_.py:315: SNIMissingWarning: An HTTPS request has been made, but the SNI (Subject Name Indication) extension to TLS is not available on this platform. This may cause the server to present an incorrect TLS certificate, which can cause validation failures. For more information, see https://urllib3.readthedocs.org/en/latest/security.html#snimissingwarning.
  SNIMissingWarning

WARNING:py.warnings:/usr/local/lib/python2.7/dist-packages/requests/packages/urllib3/util/ssl_.py:120: InsecurePlatformWarning: A true SSLContext object is not available. This prevents urllib3 from configuring SSL appropriately and may cause certain SSL connections to fail. For more information, see https://urllib3.readthedocs.org/en/latest/security.html#insecureplatformwarning.
  InsecurePlatformWarning

INFO:requests.packages.urllib3.connectionpool:Starting new HTTPS connection (1): twitter.com
WARNING:py.warnings:/usr/local/lib/python2.7/dist-packages/requests/packages/urllib3/util/ssl_.py:120: InsecurePlatformWarning: A true SSLContext object is not available. This prevents urllib3 from configuring SSL appropriately and may cause certain SSL connections to fail. For more information, see https://urllib3.readthedocs.org/en/latest/security.html#insecureplatformwarning.
  InsecurePlatformWarning

ERROR:django.request:Internal Server Error: /battles/start_crawling/
Traceback (most recent call last):
  File "/usr/local/lib/python2.7/dist-packages/django/core/handlers/base.py", line 149, in get_response
    response = self.process_exception_by_middleware(e, request)
  File "/usr/local/lib/python2.7/dist-packages/django/core/handlers/base.py", line 147, in get_response
    response = wrapped_callback(request, *callback_args, **callback_kwargs)
  File "/home/neelu/twitter_crawl/hashtagbattle/views.py", line 156, in start_crawling
    crawl_twitter(request)
  File "/home/neelu/twitter_crawl/hashtagbattle/views.py", line 204, in crawl_twitter
    st = update_crawl_data(battle)
  File "/home/neelu/twitter_crawl/hashtagbattle/views.py", line 185, in update_crawl_data
    tag_num_spell_errors=stats['num_spell'])
  File "/usr/local/lib/python2.7/dist-packages/django/db/models/manager.py", line 122, in manager_method
    return getattr(self.get_queryset(), name)(*args, **kwargs)
  File "/usr/local/lib/python2.7/dist-packages/django/db/models/query.py", line 480, in update_or_create
    obj = self.get(**lookup)
  File "/usr/local/lib/python2.7/dist-packages/django/db/models/query.py", line 391, in get
    (self.model._meta.object_name, num)
MultipleObjectsReturned: get() returned more than one BattleCrawlData -- it returned 6!
INFO:apscheduler.scheduler:Scheduler started
INFO:requests.packages.urllib3.connectionpool:Starting new HTTPS connection (1): twitter.com
WARNING:py.warnings:/usr/local/lib/python2.7/dist-packages/requests/packages/urllib3/util/ssl_.py:315: SNIMissingWarning: An HTTPS request has been made, but the SNI (Subject Name Indication) extension to TLS is not available on this platform. This may cause the server to present an incorrect TLS certificate, which can cause validation failures. For more information, see https://urllib3.readthedocs.org/en/latest/security.html#snimissingwarning.
  SNIMissingWarning

WARNING:py.warnings:/usr/local/lib/python2.7/dist-packages/requests/packages/urllib3/util/ssl_.py:120: InsecurePlatformWarning: A true SSLContext object is not available. This prevents urllib3 from configuring SSL appropriately and may cause certain SSL connections to fail. For more information, see https://urllib3.readthedocs.org/en/latest/security.html#insecureplatformwarning.
  InsecurePlatformWarning

INFO:requests.packages.urllib3.connectionpool:Starting new HTTPS connection (1): twitter.com
WARNING:py.warnings:/usr/local/lib/python2.7/dist-packages/requests/packages/urllib3/util/ssl_.py:120: InsecurePlatformWarning: A true SSLContext object is not available. This prevents urllib3 from configuring SSL appropriately and may cause certain SSL connections to fail. For more information, see https://urllib3.readthedocs.org/en/latest/security.html#insecureplatformwarning.
  InsecurePlatformWarning

ERROR:django.request:Internal Server Error: /battles/start_crawling/
Traceback (most recent call last):
  File "/usr/local/lib/python2.7/dist-packages/django/core/handlers/base.py", line 149, in get_response
    response = self.process_exception_by_middleware(e, request)
  File "/usr/local/lib/python2.7/dist-packages/django/core/handlers/base.py", line 147, in get_response
    response = wrapped_callback(request, *callback_args, **callback_kwargs)
  File "/home/neelu/twitter_crawl/hashtagbattle/views.py", line 156, in start_crawling
    crawl_twitter(request)
  File "/home/neelu/twitter_crawl/hashtagbattle/views.py", line 205, in crawl_twitter
    st = update_crawl_data(battle)
  File "/home/neelu/twitter_crawl/hashtagbattle/views.py", line 187, in update_crawl_data
    b.save()
AttributeError: 'tuple' object has no attribute 'save'
INFO:apscheduler.scheduler:Scheduler started
INFO:requests.packages.urllib3.connectionpool:Starting new HTTPS connection (1): twitter.com
WARNING:py.warnings:/usr/local/lib/python2.7/dist-packages/requests/packages/urllib3/util/ssl_.py:315: SNIMissingWarning: An HTTPS request has been made, but the SNI (Subject Name Indication) extension to TLS is not available on this platform. This may cause the server to present an incorrect TLS certificate, which can cause validation failures. For more information, see https://urllib3.readthedocs.org/en/latest/security.html#snimissingwarning.
  SNIMissingWarning

WARNING:py.warnings:/usr/local/lib/python2.7/dist-packages/requests/packages/urllib3/util/ssl_.py:120: InsecurePlatformWarning: A true SSLContext object is not available. This prevents urllib3 from configuring SSL appropriately and may cause certain SSL connections to fail. For more information, see https://urllib3.readthedocs.org/en/latest/security.html#insecureplatformwarning.
  InsecurePlatformWarning

INFO:requests.packages.urllib3.connectionpool:Starting new HTTPS connection (1): twitter.com
WARNING:py.warnings:/usr/local/lib/python2.7/dist-packages/requests/packages/urllib3/util/ssl_.py:120: InsecurePlatformWarning: A true SSLContext object is not available. This prevents urllib3 from configuring SSL appropriately and may cause certain SSL connections to fail. For more information, see https://urllib3.readthedocs.org/en/latest/security.html#insecureplatformwarning.
  InsecurePlatformWarning

INFO:apscheduler.scheduler:Scheduler started
INFO:requests.packages.urllib3.connectionpool:Starting new HTTPS connection (1): twitter.com
WARNING:py.warnings:/usr/local/lib/python2.7/dist-packages/requests/packages/urllib3/util/ssl_.py:315: SNIMissingWarning: An HTTPS request has been made, but the SNI (Subject Name Indication) extension to TLS is not available on this platform. This may cause the server to present an incorrect TLS certificate, which can cause validation failures. For more information, see https://urllib3.readthedocs.org/en/latest/security.html#snimissingwarning.
  SNIMissingWarning

WARNING:py.warnings:/usr/local/lib/python2.7/dist-packages/requests/packages/urllib3/util/ssl_.py:120: InsecurePlatformWarning: A true SSLContext object is not available. This prevents urllib3 from configuring SSL appropriately and may cause certain SSL connections to fail. For more information, see https://urllib3.readthedocs.org/en/latest/security.html#insecureplatformwarning.
  InsecurePlatformWarning

INFO:requests.packages.urllib3.connectionpool:Starting new HTTPS connection (1): twitter.com
WARNING:py.warnings:/usr/local/lib/python2.7/dist-packages/requests/packages/urllib3/util/ssl_.py:120: InsecurePlatformWarning: A true SSLContext object is not available. This prevents urllib3 from configuring SSL appropriately and may cause certain SSL connections to fail. For more information, see https://urllib3.readthedocs.org/en/latest/security.html#insecureplatformwarning.
  InsecurePlatformWarning

ERROR:django.request:Internal Server Error: /battles/
Traceback (most recent call last):
  File "/usr/local/lib/python2.7/dist-packages/django/core/handlers/base.py", line 149, in get_response
    response = self.process_exception_by_middleware(e, request)
  File "/usr/local/lib/python2.7/dist-packages/django/core/handlers/base.py", line 147, in get_response
    response = wrapped_callback(request, *callback_args, **callback_kwargs)
  File "/home/neelu/twitter_crawl/hashtagbattle/views.py", line 77, in battle_list
    return render(request, "battle_list.html", context)
  File "/usr/local/lib/python2.7/dist-packages/django/shortcuts.py", line 67, in render
    template_name, context, request=request, using=using)
  File "/usr/local/lib/python2.7/dist-packages/django/template/loader.py", line 97, in render_to_string
    return template.render(context, request)
  File "/usr/local/lib/python2.7/dist-packages/django/template/backends/django.py", line 95, in render
    return self.template.render(context)
  File "/usr/local/lib/python2.7/dist-packages/django/template/base.py", line 206, in render
    return self._render(context)
  File "/usr/local/lib/python2.7/dist-packages/django/template/base.py", line 197, in _render
    return self.nodelist.render(context)
  File "/usr/local/lib/python2.7/dist-packages/django/template/base.py", line 992, in render
    bit = node.render_annotated(context)
  File "/usr/local/lib/python2.7/dist-packages/django/template/base.py", line 959, in render_annotated
    return self.render(context)
  File "/usr/local/lib/python2.7/dist-packages/django/template/loader_tags.py", line 173, in render
    return compiled_parent._render(context)
  File "/usr/local/lib/python2.7/dist-packages/django/template/base.py", line 197, in _render
    return self.nodelist.render(context)
  File "/usr/local/lib/python2.7/dist-packages/django/template/base.py", line 992, in render
    bit = node.render_annotated(context)
  File "/usr/local/lib/python2.7/dist-packages/django/template/base.py", line 959, in render_annotated
    return self.render(context)
  File "/usr/local/lib/python2.7/dist-packages/django/template/loader_tags.py", line 69, in render
    result = block.nodelist.render(context)
  File "/usr/local/lib/python2.7/dist-packages/django/template/base.py", line 992, in render
    bit = node.render_annotated(context)
  File "/usr/local/lib/python2.7/dist-packages/django/template/base.py", line 959, in render_annotated
    return self.render(context)
  File "/usr/local/lib/python2.7/dist-packages/django/template/defaulttags.py", line 168, in render
    len_values = len(values)
  File "/usr/local/lib/python2.7/dist-packages/django/core/paginator.py", line 117, in __len__
    return len(self.object_list)
  File "/usr/local/lib/python2.7/dist-packages/django/db/models/query.py", line 240, in __len__
    self._fetch_all()
  File "/usr/local/lib/python2.7/dist-packages/django/db/models/query.py", line 1074, in _fetch_all
    self._result_cache = list(self.iterator())
  File "/usr/local/lib/python2.7/dist-packages/django/db/models/query.py", line 52, in __iter__
    results = compiler.execute_sql()
  File "/usr/local/lib/python2.7/dist-packages/django/db/models/sql/compiler.py", line 848, in execute_sql
    cursor.execute(sql, params)
  File "/usr/local/lib/python2.7/dist-packages/django/db/backends/utils.py", line 79, in execute
    return super(CursorDebugWrapper, self).execute(sql, params)
  File "/usr/local/lib/python2.7/dist-packages/django/db/backends/utils.py", line 64, in execute
    return self.cursor.execute(sql, params)
  File "/usr/local/lib/python2.7/dist-packages/django/db/utils.py", line 95, in __exit__
    six.reraise(dj_exc_type, dj_exc_value, traceback)
  File "/usr/local/lib/python2.7/dist-packages/django/db/backends/utils.py", line 64, in execute
    return self.cursor.execute(sql, params)
  File "/usr/local/lib/python2.7/dist-packages/django/db/backends/sqlite3/base.py", line 323, in execute
    return Database.Cursor.execute(self, query, params)
OperationalError: no such column: hashtagbattle_battle.tag1_num_tweets
ERROR:django.request:Internal Server Error: /battles/
Traceback (most recent call last):
  File "/usr/local/lib/python2.7/dist-packages/django/core/handlers/base.py", line 149, in get_response
    response = self.process_exception_by_middleware(e, request)
  File "/usr/local/lib/python2.7/dist-packages/django/core/handlers/base.py", line 147, in get_response
    response = wrapped_callback(request, *callback_args, **callback_kwargs)
  File "/home/neelu/twitter_crawl/hashtagbattle/views.py", line 77, in battle_list
    return render(request, "battle_list.html", context)
  File "/usr/local/lib/python2.7/dist-packages/django/shortcuts.py", line 67, in render
    template_name, context, request=request, using=using)
  File "/usr/local/lib/python2.7/dist-packages/django/template/loader.py", line 97, in render_to_string
    return template.render(context, request)
  File "/usr/local/lib/python2.7/dist-packages/django/template/backends/django.py", line 95, in render
    return self.template.render(context)
  File "/usr/local/lib/python2.7/dist-packages/django/template/base.py", line 206, in render
    return self._render(context)
  File "/usr/local/lib/python2.7/dist-packages/django/template/base.py", line 197, in _render
    return self.nodelist.render(context)
  File "/usr/local/lib/python2.7/dist-packages/django/template/base.py", line 992, in render
    bit = node.render_annotated(context)
  File "/usr/local/lib/python2.7/dist-packages/django/template/base.py", line 959, in render_annotated
    return self.render(context)
  File "/usr/local/lib/python2.7/dist-packages/django/template/loader_tags.py", line 173, in render
    return compiled_parent._render(context)
  File "/usr/local/lib/python2.7/dist-packages/django/template/base.py", line 197, in _render
    return self.nodelist.render(context)
  File "/usr/local/lib/python2.7/dist-packages/django/template/base.py", line 992, in render
    bit = node.render_annotated(context)
  File "/usr/local/lib/python2.7/dist-packages/django/template/base.py", line 959, in render_annotated
    return self.render(context)
  File "/usr/local/lib/python2.7/dist-packages/django/template/loader_tags.py", line 69, in render
    result = block.nodelist.render(context)
  File "/usr/local/lib/python2.7/dist-packages/django/template/base.py", line 992, in render
    bit = node.render_annotated(context)
  File "/usr/local/lib/python2.7/dist-packages/django/template/base.py", line 959, in render_annotated
    return self.render(context)
  File "/usr/local/lib/python2.7/dist-packages/django/template/defaulttags.py", line 168, in render
    len_values = len(values)
  File "/usr/local/lib/python2.7/dist-packages/django/core/paginator.py", line 117, in __len__
    return len(self.object_list)
  File "/usr/local/lib/python2.7/dist-packages/django/db/models/query.py", line 240, in __len__
    self._fetch_all()
  File "/usr/local/lib/python2.7/dist-packages/django/db/models/query.py", line 1074, in _fetch_all
    self._result_cache = list(self.iterator())
  File "/usr/local/lib/python2.7/dist-packages/django/db/models/query.py", line 52, in __iter__
    results = compiler.execute_sql()
  File "/usr/local/lib/python2.7/dist-packages/django/db/models/sql/compiler.py", line 848, in execute_sql
    cursor.execute(sql, params)
  File "/usr/local/lib/python2.7/dist-packages/django/db/backends/utils.py", line 79, in execute
    return super(CursorDebugWrapper, self).execute(sql, params)
  File "/usr/local/lib/python2.7/dist-packages/django/db/backends/utils.py", line 64, in execute
    return self.cursor.execute(sql, params)
  File "/usr/local/lib/python2.7/dist-packages/django/db/utils.py", line 95, in __exit__
    six.reraise(dj_exc_type, dj_exc_value, traceback)
  File "/usr/local/lib/python2.7/dist-packages/django/db/backends/utils.py", line 64, in execute
    return self.cursor.execute(sql, params)
  File "/usr/local/lib/python2.7/dist-packages/django/db/backends/sqlite3/base.py", line 323, in execute
    return Database.Cursor.execute(self, query, params)
OperationalError: no such column: hashtagbattle_battle.tag1_num_tweets
ERROR:django.request:Internal Server Error: /battles/
Traceback (most recent call last):
  File "/usr/local/lib/python2.7/dist-packages/django/core/handlers/base.py", line 149, in get_response
    response = self.process_exception_by_middleware(e, request)
  File "/usr/local/lib/python2.7/dist-packages/django/core/handlers/base.py", line 147, in get_response
    response = wrapped_callback(request, *callback_args, **callback_kwargs)
  File "/home/neelu/twitter_crawl/hashtagbattle/views.py", line 77, in battle_list
    return render(request, "battle_list.html", context)
  File "/usr/local/lib/python2.7/dist-packages/django/shortcuts.py", line 67, in render
    template_name, context, request=request, using=using)
  File "/usr/local/lib/python2.7/dist-packages/django/template/loader.py", line 97, in render_to_string
    return template.render(context, request)
  File "/usr/local/lib/python2.7/dist-packages/django/template/backends/django.py", line 95, in render
    return self.template.render(context)
  File "/usr/local/lib/python2.7/dist-packages/django/template/base.py", line 206, in render
    return self._render(context)
  File "/usr/local/lib/python2.7/dist-packages/django/template/base.py", line 197, in _render
    return self.nodelist.render(context)
  File "/usr/local/lib/python2.7/dist-packages/django/template/base.py", line 992, in render
    bit = node.render_annotated(context)
  File "/usr/local/lib/python2.7/dist-packages/django/template/base.py", line 959, in render_annotated
    return self.render(context)
  File "/usr/local/lib/python2.7/dist-packages/django/template/loader_tags.py", line 173, in render
    return compiled_parent._render(context)
  File "/usr/local/lib/python2.7/dist-packages/django/template/base.py", line 197, in _render
    return self.nodelist.render(context)
  File "/usr/local/lib/python2.7/dist-packages/django/template/base.py", line 992, in render
    bit = node.render_annotated(context)
  File "/usr/local/lib/python2.7/dist-packages/django/template/base.py", line 959, in render_annotated
    return self.render(context)
  File "/usr/local/lib/python2.7/dist-packages/django/template/loader_tags.py", line 69, in render
    result = block.nodelist.render(context)
  File "/usr/local/lib/python2.7/dist-packages/django/template/base.py", line 992, in render
    bit = node.render_annotated(context)
  File "/usr/local/lib/python2.7/dist-packages/django/template/base.py", line 959, in render_annotated
    return self.render(context)
  File "/usr/local/lib/python2.7/dist-packages/django/template/defaulttags.py", line 168, in render
    len_values = len(values)
  File "/usr/local/lib/python2.7/dist-packages/django/core/paginator.py", line 117, in __len__
    return len(self.object_list)
  File "/usr/local/lib/python2.7/dist-packages/django/db/models/query.py", line 240, in __len__
    self._fetch_all()
  File "/usr/local/lib/python2.7/dist-packages/django/db/models/query.py", line 1074, in _fetch_all
    self._result_cache = list(self.iterator())
  File "/usr/local/lib/python2.7/dist-packages/django/db/models/query.py", line 52, in __iter__
    results = compiler.execute_sql()
  File "/usr/local/lib/python2.7/dist-packages/django/db/models/sql/compiler.py", line 848, in execute_sql
    cursor.execute(sql, params)
  File "/usr/local/lib/python2.7/dist-packages/django/db/backends/utils.py", line 79, in execute
    return super(CursorDebugWrapper, self).execute(sql, params)
  File "/usr/local/lib/python2.7/dist-packages/django/db/backends/utils.py", line 64, in execute
    return self.cursor.execute(sql, params)
  File "/usr/local/lib/python2.7/dist-packages/django/db/utils.py", line 95, in __exit__
    six.reraise(dj_exc_type, dj_exc_value, traceback)
  File "/usr/local/lib/python2.7/dist-packages/django/db/backends/utils.py", line 64, in execute
    return self.cursor.execute(sql, params)
  File "/usr/local/lib/python2.7/dist-packages/django/db/backends/sqlite3/base.py", line 323, in execute
    return Database.Cursor.execute(self, query, params)
OperationalError: no such column: hashtagbattle_battle.tag1_num_tweets
WARNING:py.warnings:/usr/local/lib/python2.7/dist-packages/django/db/models/fields/__init__.py:1453: RuntimeWarning: DateTimeField Battle.battle_end received a naive datetime (2016-03-11 16:25:48.538406) while time zone support is active.
  RuntimeWarning)

ERROR:django.request:Internal Server Error: /battles/create/
Traceback (most recent call last):
  File "/usr/local/lib/python2.7/dist-packages/django/core/handlers/base.py", line 149, in get_response
    response = self.process_exception_by_middleware(e, request)
  File "/usr/local/lib/python2.7/dist-packages/django/core/handlers/base.py", line 147, in get_response
    response = wrapped_callback(request, *callback_args, **callback_kwargs)
  File "/home/neelu/twitter_crawl/hashtagbattle/views.py", line 33, in battle_create
    instance.save()
  File "/usr/local/lib/python2.7/dist-packages/django/db/models/base.py", line 700, in save
    force_update=force_update, update_fields=update_fields)
  File "/usr/local/lib/python2.7/dist-packages/django/db/models/base.py", line 728, in save_base
    updated = self._save_table(raw, cls, force_insert, force_update, using, update_fields)
  File "/usr/local/lib/python2.7/dist-packages/django/db/models/base.py", line 812, in _save_table
    result = self._do_insert(cls._base_manager, using, fields, update_pk, raw)
  File "/usr/local/lib/python2.7/dist-packages/django/db/models/base.py", line 851, in _do_insert
    using=using, raw=raw)
  File "/usr/local/lib/python2.7/dist-packages/django/db/models/manager.py", line 122, in manager_method
    return getattr(self.get_queryset(), name)(*args, **kwargs)
  File "/usr/local/lib/python2.7/dist-packages/django/db/models/query.py", line 1039, in _insert
    return query.get_compiler(using=using).execute_sql(return_id)
  File "/usr/local/lib/python2.7/dist-packages/django/db/models/sql/compiler.py", line 1060, in execute_sql
    cursor.execute(sql, params)
  File "/usr/local/lib/python2.7/dist-packages/django/db/backends/utils.py", line 79, in execute
    return super(CursorDebugWrapper, self).execute(sql, params)
  File "/usr/local/lib/python2.7/dist-packages/django/db/backends/utils.py", line 64, in execute
    return self.cursor.execute(sql, params)
  File "/usr/local/lib/python2.7/dist-packages/django/db/utils.py", line 95, in __exit__
    six.reraise(dj_exc_type, dj_exc_value, traceback)
  File "/usr/local/lib/python2.7/dist-packages/django/db/backends/utils.py", line 64, in execute
    return self.cursor.execute(sql, params)
  File "/usr/local/lib/python2.7/dist-packages/django/db/backends/sqlite3/base.py", line 323, in execute
    return Database.Cursor.execute(self, query, params)
OperationalError: table hashtagbattle_battle has no column named tag1_num_tweets
WARNING:py.warnings:/usr/local/lib/python2.7/dist-packages/django/db/models/fields/__init__.py:1453: RuntimeWarning: DateTimeField Battle.battle_end received a naive datetime (2016-03-11 16:34:30.057877) while time zone support is active.
  RuntimeWarning)

INFO:requests.packages.urllib3.connectionpool:Starting new HTTPS connection (1): twitter.com
WARNING:py.warnings:/usr/local/lib/python2.7/dist-packages/requests/packages/urllib3/util/ssl_.py:315: SNIMissingWarning: An HTTPS request has been made, but the SNI (Subject Name Indication) extension to TLS is not available on this platform. This may cause the server to present an incorrect TLS certificate, which can cause validation failures. For more information, see https://urllib3.readthedocs.org/en/latest/security.html#snimissingwarning.
  SNIMissingWarning

WARNING:py.warnings:/usr/local/lib/python2.7/dist-packages/requests/packages/urllib3/util/ssl_.py:120: InsecurePlatformWarning: A true SSLContext object is not available. This prevents urllib3 from configuring SSL appropriately and may cause certain SSL connections to fail. For more information, see https://urllib3.readthedocs.org/en/latest/security.html#insecureplatformwarning.
  InsecurePlatformWarning

INFO:requests.packages.urllib3.connectionpool:Starting new HTTPS connection (1): twitter.com
WARNING:py.warnings:/usr/local/lib/python2.7/dist-packages/requests/packages/urllib3/util/ssl_.py:120: InsecurePlatformWarning: A true SSLContext object is not available. This prevents urllib3 from configuring SSL appropriately and may cause certain SSL connections to fail. For more information, see https://urllib3.readthedocs.org/en/latest/security.html#insecureplatformwarning.
  InsecurePlatformWarning

INFO:requests.packages.urllib3.connectionpool:Starting new HTTPS connection (1): twitter.com
WARNING:py.warnings:/usr/local/lib/python2.7/dist-packages/requests/packages/urllib3/util/ssl_.py:120: InsecurePlatformWarning: A true SSLContext object is not available. This prevents urllib3 from configuring SSL appropriately and may cause certain SSL connections to fail. For more information, see https://urllib3.readthedocs.org/en/latest/security.html#insecureplatformwarning.
  InsecurePlatformWarning

INFO:requests.packages.urllib3.connectionpool:Starting new HTTPS connection (1): twitter.com
WARNING:py.warnings:/usr/local/lib/python2.7/dist-packages/requests/packages/urllib3/util/ssl_.py:120: InsecurePlatformWarning: A true SSLContext object is not available. This prevents urllib3 from configuring SSL appropriately and may cause certain SSL connections to fail. For more information, see https://urllib3.readthedocs.org/en/latest/security.html#insecureplatformwarning.
  InsecurePlatformWarning

INFO:requests.packages.urllib3.connectionpool:Starting new HTTPS connection (1): twitter.com
WARNING:py.warnings:/usr/local/lib/python2.7/dist-packages/requests/packages/urllib3/util/ssl_.py:315: SNIMissingWarning: An HTTPS request has been made, but the SNI (Subject Name Indication) extension to TLS is not available on this platform. This may cause the server to present an incorrect TLS certificate, which can cause validation failures. For more information, see https://urllib3.readthedocs.org/en/latest/security.html#snimissingwarning.
  SNIMissingWarning

WARNING:py.warnings:/usr/local/lib/python2.7/dist-packages/requests/packages/urllib3/util/ssl_.py:120: InsecurePlatformWarning: A true SSLContext object is not available. This prevents urllib3 from configuring SSL appropriately and may cause certain SSL connections to fail. For more information, see https://urllib3.readthedocs.org/en/latest/security.html#insecureplatformwarning.
  InsecurePlatformWarning

INFO:requests.packages.urllib3.connectionpool:Starting new HTTPS connection (1): twitter.com
WARNING:py.warnings:/usr/local/lib/python2.7/dist-packages/requests/packages/urllib3/util/ssl_.py:120: InsecurePlatformWarning: A true SSLContext object is not available. This prevents urllib3 from configuring SSL appropriately and may cause certain SSL connections to fail. For more information, see https://urllib3.readthedocs.org/en/latest/security.html#insecureplatformwarning.
  InsecurePlatformWarning

INFO:requests.packages.urllib3.connectionpool:Starting new HTTPS connection (1): twitter.com
WARNING:py.warnings:/usr/local/lib/python2.7/dist-packages/requests/packages/urllib3/util/ssl_.py:315: SNIMissingWarning: An HTTPS request has been made, but the SNI (Subject Name Indication) extension to TLS is not available on this platform. This may cause the server to present an incorrect TLS certificate, which can cause validation failures. For more information, see https://urllib3.readthedocs.org/en/latest/security.html#snimissingwarning.
  SNIMissingWarning

WARNING:py.warnings:/usr/local/lib/python2.7/dist-packages/requests/packages/urllib3/util/ssl_.py:120: InsecurePlatformWarning: A true SSLContext object is not available. This prevents urllib3 from configuring SSL appropriately and may cause certain SSL connections to fail. For more information, see https://urllib3.readthedocs.org/en/latest/security.html#insecureplatformwarning.
  InsecurePlatformWarning

INFO:requests.packages.urllib3.connectionpool:Starting new HTTPS connection (1): twitter.com
WARNING:py.warnings:/usr/local/lib/python2.7/dist-packages/requests/packages/urllib3/util/ssl_.py:120: InsecurePlatformWarning: A true SSLContext object is not available. This prevents urllib3 from configuring SSL appropriately and may cause certain SSL connections to fail. For more information, see https://urllib3.readthedocs.org/en/latest/security.html#insecureplatformwarning.
  InsecurePlatformWarning

INFO:requests.packages.urllib3.connectionpool:Starting new HTTPS connection (1): twitter.com
WARNING:py.warnings:/usr/local/lib/python2.7/dist-packages/requests/packages/urllib3/util/ssl_.py:120: InsecurePlatformWarning: A true SSLContext object is not available. This prevents urllib3 from configuring SSL appropriately and may cause certain SSL connections to fail. For more information, see https://urllib3.readthedocs.org/en/latest/security.html#insecureplatformwarning.
  InsecurePlatformWarning

INFO:requests.packages.urllib3.connectionpool:Starting new HTTPS connection (1): twitter.com
WARNING:py.warnings:/usr/local/lib/python2.7/dist-packages/requests/packages/urllib3/util/ssl_.py:120: InsecurePlatformWarning: A true SSLContext object is not available. This prevents urllib3 from configuring SSL appropriately and may cause certain SSL connections to fail. For more information, see https://urllib3.readthedocs.org/en/latest/security.html#insecureplatformwarning.
  InsecurePlatformWarning

INFO:apscheduler.scheduler:Scheduler started
INFO:requests.packages.urllib3.connectionpool:Starting new HTTPS connection (1): twitter.com
WARNING:py.warnings:/usr/local/lib/python2.7/dist-packages/requests/packages/urllib3/util/ssl_.py:315: SNIMissingWarning: An HTTPS request has been made, but the SNI (Subject Name Indication) extension to TLS is not available on this platform. This may cause the server to present an incorrect TLS certificate, which can cause validation failures. For more information, see https://urllib3.readthedocs.org/en/latest/security.html#snimissingwarning.
  SNIMissingWarning

WARNING:py.warnings:/usr/local/lib/python2.7/dist-packages/requests/packages/urllib3/util/ssl_.py:120: InsecurePlatformWarning: A true SSLContext object is not available. This prevents urllib3 from configuring SSL appropriately and may cause certain SSL connections to fail. For more information, see https://urllib3.readthedocs.org/en/latest/security.html#insecureplatformwarning.
  InsecurePlatformWarning

INFO:requests.packages.urllib3.connectionpool:Starting new HTTPS connection (1): twitter.com
WARNING:py.warnings:/usr/local/lib/python2.7/dist-packages/requests/packages/urllib3/util/ssl_.py:120: InsecurePlatformWarning: A true SSLContext object is not available. This prevents urllib3 from configuring SSL appropriately and may cause certain SSL connections to fail. For more information, see https://urllib3.readthedocs.org/en/latest/security.html#insecureplatformwarning.
  InsecurePlatformWarning

INFO:apscheduler.scheduler:Scheduler started
INFO:requests.packages.urllib3.connectionpool:Starting new HTTPS connection (1): twitter.com
WARNING:py.warnings:/usr/local/lib/python2.7/dist-packages/requests/packages/urllib3/util/ssl_.py:315: SNIMissingWarning: An HTTPS request has been made, but the SNI (Subject Name Indication) extension to TLS is not available on this platform. This may cause the server to present an incorrect TLS certificate, which can cause validation failures. For more information, see https://urllib3.readthedocs.org/en/latest/security.html#snimissingwarning.
  SNIMissingWarning

WARNING:py.warnings:/usr/local/lib/python2.7/dist-packages/requests/packages/urllib3/util/ssl_.py:120: InsecurePlatformWarning: A true SSLContext object is not available. This prevents urllib3 from configuring SSL appropriately and may cause certain SSL connections to fail. For more information, see https://urllib3.readthedocs.org/en/latest/security.html#insecureplatformwarning.
  InsecurePlatformWarning

INFO:requests.packages.urllib3.connectionpool:Starting new HTTPS connection (1): twitter.com
WARNING:py.warnings:/usr/local/lib/python2.7/dist-packages/requests/packages/urllib3/util/ssl_.py:120: InsecurePlatformWarning: A true SSLContext object is not available. This prevents urllib3 from configuring SSL appropriately and may cause certain SSL connections to fail. For more information, see https://urllib3.readthedocs.org/en/latest/security.html#insecureplatformwarning.
  InsecurePlatformWarning

INFO:requests.packages.urllib3.connectionpool:Starting new HTTPS connection (1): twitter.com
WARNING:py.warnings:/usr/local/lib/python2.7/dist-packages/requests/packages/urllib3/util/ssl_.py:120: InsecurePlatformWarning: A true SSLContext object is not available. This prevents urllib3 from configuring SSL appropriately and may cause certain SSL connections to fail. For more information, see https://urllib3.readthedocs.org/en/latest/security.html#insecureplatformwarning.
  InsecurePlatformWarning

INFO:requests.packages.urllib3.connectionpool:Starting new HTTPS connection (1): twitter.com
WARNING:py.warnings:/usr/local/lib/python2.7/dist-packages/requests/packages/urllib3/util/ssl_.py:120: InsecurePlatformWarning: A true SSLContext object is not available. This prevents urllib3 from configuring SSL appropriately and may cause certain SSL connections to fail. For more information, see https://urllib3.readthedocs.org/en/latest/security.html#insecureplatformwarning.
  InsecurePlatformWarning

INFO:requests.packages.urllib3.connectionpool:Starting new HTTPS connection (1): twitter.com
WARNING:py.warnings:/usr/local/lib/python2.7/dist-packages/requests/packages/urllib3/util/ssl_.py:120: InsecurePlatformWarning: A true SSLContext object is not available. This prevents urllib3 from configuring SSL appropriately and may cause certain SSL connections to fail. For more information, see https://urllib3.readthedocs.org/en/latest/security.html#insecureplatformwarning.
  InsecurePlatformWarning

INFO:requests.packages.urllib3.connectionpool:Starting new HTTPS connection (1): twitter.com
WARNING:py.warnings:/usr/local/lib/python2.7/dist-packages/requests/packages/urllib3/util/ssl_.py:120: InsecurePlatformWarning: A true SSLContext object is not available. This prevents urllib3 from configuring SSL appropriately and may cause certain SSL connections to fail. For more information, see https://urllib3.readthedocs.org/en/latest/security.html#insecureplatformwarning.
  InsecurePlatformWarning

INFO:requests.packages.urllib3.connectionpool:Starting new HTTPS connection (1): twitter.com
WARNING:py.warnings:/usr/local/lib/python2.7/dist-packages/requests/packages/urllib3/util/ssl_.py:120: InsecurePlatformWarning: A true SSLContext object is not available. This prevents urllib3 from configuring SSL appropriately and may cause certain SSL connections to fail. For more information, see https://urllib3.readthedocs.org/en/latest/security.html#insecureplatformwarning.
  InsecurePlatformWarning

INFO:requests.packages.urllib3.connectionpool:Starting new HTTPS connection (1): twitter.com
WARNING:py.warnings:/usr/local/lib/python2.7/dist-packages/requests/packages/urllib3/util/ssl_.py:120: InsecurePlatformWarning: A true SSLContext object is not available. This prevents urllib3 from configuring SSL appropriately and may cause certain SSL connections to fail. For more information, see https://urllib3.readthedocs.org/en/latest/security.html#insecureplatformwarning.
  InsecurePlatformWarning

INFO:requests.packages.urllib3.connectionpool:Starting new HTTPS connection (1): twitter.com
WARNING:py.warnings:/usr/local/lib/python2.7/dist-packages/requests/packages/urllib3/util/ssl_.py:120: InsecurePlatformWarning: A true SSLContext object is not available. This prevents urllib3 from configuring SSL appropriately and may cause certain SSL connections to fail. For more information, see https://urllib3.readthedocs.org/en/latest/security.html#insecureplatformwarning.
  InsecurePlatformWarning

INFO:requests.packages.urllib3.connectionpool:Starting new HTTPS connection (1): twitter.com
WARNING:py.warnings:/usr/local/lib/python2.7/dist-packages/requests/packages/urllib3/util/ssl_.py:120: InsecurePlatformWarning: A true SSLContext object is not available. This prevents urllib3 from configuring SSL appropriately and may cause certain SSL connections to fail. For more information, see https://urllib3.readthedocs.org/en/latest/security.html#insecureplatformwarning.
  InsecurePlatformWarning

INFO:requests.packages.urllib3.connectionpool:Starting new HTTPS connection (1): twitter.com
WARNING:py.warnings:/usr/local/lib/python2.7/dist-packages/requests/packages/urllib3/util/ssl_.py:120: InsecurePlatformWarning: A true SSLContext object is not available. This prevents urllib3 from configuring SSL appropriately and may cause certain SSL connections to fail. For more information, see https://urllib3.readthedocs.org/en/latest/security.html#insecureplatformwarning.
  InsecurePlatformWarning

INFO:requests.packages.urllib3.connectionpool:Starting new HTTPS connection (1): twitter.com
WARNING:py.warnings:/usr/local/lib/python2.7/dist-packages/requests/packages/urllib3/util/ssl_.py:120: InsecurePlatformWarning: A true SSLContext object is not available. This prevents urllib3 from configuring SSL appropriately and may cause certain SSL connections to fail. For more information, see https://urllib3.readthedocs.org/en/latest/security.html#insecureplatformwarning.
  InsecurePlatformWarning

WARNING:django.request:Not Found: /favicon.ico
WARNING:django.request:Not Found: /favicon.ico
INFO:requests.packages.urllib3.connectionpool:Starting new HTTPS connection (1): twitter.com
WARNING:py.warnings:/usr/local/lib/python2.7/dist-packages/requests/packages/urllib3/util/ssl_.py:315: SNIMissingWarning: An HTTPS request has been made, but the SNI (Subject Name Indication) extension to TLS is not available on this platform. This may cause the server to present an incorrect TLS certificate, which can cause validation failures. For more information, see https://urllib3.readthedocs.org/en/latest/security.html#snimissingwarning.
  SNIMissingWarning

WARNING:py.warnings:/usr/local/lib/python2.7/dist-packages/requests/packages/urllib3/util/ssl_.py:120: InsecurePlatformWarning: A true SSLContext object is not available. This prevents urllib3 from configuring SSL appropriately and may cause certain SSL connections to fail. For more information, see https://urllib3.readthedocs.org/en/latest/security.html#insecureplatformwarning.
  InsecurePlatformWarning

INFO:requests.packages.urllib3.connectionpool:Starting new HTTPS connection (1): twitter.com
WARNING:py.warnings:/usr/local/lib/python2.7/dist-packages/requests/packages/urllib3/util/ssl_.py:120: InsecurePlatformWarning: A true SSLContext object is not available. This prevents urllib3 from configuring SSL appropriately and may cause certain SSL connections to fail. For more information, see https://urllib3.readthedocs.org/en/latest/security.html#insecureplatformwarning.
  InsecurePlatformWarning

